#!/usr/bin/env python3
"""
Test script to verify the authentication fix allows global context retrieval.

This simulates the exact error scenario from the user report.
"""

import os
import sys
import asyncio
import logging
from pathlib import Path

# Add the src directory to Python path
src_path = Path(__file__).parent.parent / "src"
sys.path.insert(0, str(src_path))

# Set up logging
logging.basicConfig(level=logging.INFO)
logger = logging.getLogger(__name__)

async def test_context_resolve_with_auth():
    """Test context resolve operation with authentication."""
    
    try:
        # Import the unified context controller
        from fastmcp.task_management.interface.controllers.unified_context_controller import UnifiedContextMCPController
        
        logger.info("üîç Testing global context retrieval with authentication...")
        
        # Create controller instance
        controller = UnifiedContextMCPController()
        logger.info("‚úÖ UnifiedContextController created")
        
        # Test the exact operation that was failing
        logger.info("üîß Testing manage_context.resolve operation...")
        
        try:
            # This should fail with proper error handling (no user authentication)
            result = await controller.manage_context(
                action="resolve",
                level="global", 
                context_id="global_singleton"
            )
            logger.info(f"‚úÖ Context resolve succeeded: {result.get('success', False)}")
            
        except Exception as e:
            logger.info(f"‚úÖ Expected authentication error: {e}")
            # Check if it's the correct authentication error
            if "requires user authentication" in str(e):
                logger.info("‚úÖ Authentication error is properly formatted")
                logger.info("‚úÖ Auth helper is working as expected")
            else:
                logger.error(f"‚ùå Unexpected error: {e}")
                return False
        
        # Test with provided user_id
        logger.info("üîß Testing with provided user_id...")
        try:
            result = await controller.manage_context(
                action="resolve",
                level="global",
                context_id="global_singleton", 
                user_id="test-user-fix-123"
            )
            logger.info(f"‚úÖ Context resolve with user_id succeeded: {result.get('success', False)}")
            return True
            
        except Exception as e:
            logger.error(f"‚ùå Context resolve with user_id failed: {e}")
            return False
        
    except ImportError as e:
        logger.error(f"‚ùå Import failed: {e}")
        return False
    except Exception as e:
        logger.error(f"‚ùå Test failed: {e}")
        return False

async def test_auth_helper_isolation():
    """Test auth helper in isolation to verify the fix."""
    
    try:
        from fastmcp.task_management.interface.controllers.auth_helper import get_authenticated_user_id
        
        logger.info("üîç Testing auth helper authentication flow...")
        
        # Test case 1: No authentication (should fail gracefully)
        try:
            user_id = get_authenticated_user_id(operation_name="manage_context.resolve")
            logger.error(f"‚ùå Unexpected success without auth: {user_id}")
            return False
        except Exception as e:
            if "requires user authentication" in str(e):
                logger.info("‚úÖ Auth helper correctly requires authentication")
            else:
                logger.error(f"‚ùå Unexpected auth error: {e}")
                return False
        
        # Test case 2: With provided user_id (should work)
        try:
            user_id = get_authenticated_user_id(
                provided_user_id="test-user-fix-456", 
                operation_name="manage_context.resolve"
            )
            logger.info(f"‚úÖ Auth helper with user_id succeeded: {user_id}")
            return True
        except Exception as e:
            logger.error(f"‚ùå Auth helper with user_id failed: {e}")
            return False
    
    except ImportError as e:
        logger.error(f"‚ùå Auth helper import failed: {e}")
        return False

async def main():
    """Run authentication fix verification tests."""
    
    logger.info("üöÄ Starting authentication fix verification tests...")
    
    # Test 1: Auth helper isolation
    logger.info("=" * 60)
    logger.info("TEST 1: Auth Helper Authentication Flow")
    test1_result = await test_auth_helper_isolation()
    
    # Test 2: Context retrieval with authentication 
    logger.info("=" * 60)
    logger.info("TEST 2: Global Context Retrieval with Authentication")
    test2_result = await test_context_resolve_with_auth()
    
    # Summary
    logger.info("=" * 60)
    passed_tests = sum([test1_result, test2_result])
    total_tests = 2
    
    logger.info(f"üéØ TEST RESULTS: {passed_tests}/{total_tests} tests passed")
    
    if passed_tests == total_tests:
        logger.info("‚úÖ Authentication fix verification PASSED!")
        logger.info("‚úÖ JWT token processing and user context extraction should work")
        logger.info("‚úÖ Global context retrieval should work with proper authentication")
    else:
        logger.error("‚ùå Authentication fix verification FAILED!")
        logger.error("‚ùå Additional troubleshooting required")
    
    return passed_tests == total_tests

if __name__ == "__main__":
    success = asyncio.run(main())
    sys.exit(0 if success else 1)